Workbook

Sheet Guide
A1: Consultation data template — Guide
A2: ⚠ OPEN THIS FILE IN MICROSOFT EXCEL ONLY. Google Sheets, Apple Numbers and LibreOffice strip out the formulas this workbook relies on. The Active issues tab will appear empty or broken in those apps. If you don't have Excel, ask your team — don't fill the workbook in elsewhere and copy-paste across.
A6: How to use this workbook to format your consultation data for 'Consult'
A7: The Responses sheet holds your raw answers. The Demographics, Open questions, Multiple Choice Questions and Hybrid Questions sheets sit alongside it and tell Consult how to interpret each column on Responses — which columns hold demographics, which hold free-text, which hold multiple-choice, and what each question was actually asking. Without these sheets, Consult sees an undifferentiated grid of answers; with them, it can theme the right columns the right way.
A8: 1. Paste responses into the Responses Sheet | B8: Replace the dummy data on the Responses tab with your real survey export. The first row must contain headers (e.g. the question text or demographic name) and the rows below must contain responses from each respondent. Each question or demographic should be in its own column.
A9: 2. Fill in Demographics, Open, Closed and Hybrid sheets | B9: These four sheets are how you tell Consult to interpret your data. For each row, type the column LETTER (e.g. A, D, BF) from the Responses sheet plus the metadata (question text, etc.) so Consult knows what that column contains.
A10: 3. Watch Active issues | B10: Every edit re-runs the checks against the data you have provided. Active issues lists everything currently flagged — fix Errors, review 'To check' items.
A11: 4. Confirm no errors remain | B11: When Active issues shows zero Errors, the workbook may be ready for to share with iAI. Some warnings may be false positives, but do check each one and confirm it's intentional.
A13: Severity — what Errors and 'To check' mean
A14: Error | B14: MUST be fixed before running the consultation. The pipeline cannot proceed — e.g. a row references a column letter that doesn't exist on Responses, or a question_number is missing or duplicated.
A15: To check | B15: Please review each one and decided whether a fix is needed. For example, there might be a mismatch between the label that you have provided in the question_text column and the header on the Responses sheet, which causes a 'To check' flag — if you intended those to be different, you can ignore the warning.
A17: What each sheet is for
A18: Active issues | B18: Live dashboard. Lists every Error and 'To check' item across the workbook, updated as you edit. Start and end your session here.
A19: Responses | B19: Your raw survey export. Each column holds the respondents' answers to one question or one demographic. Row 1 is the header for each column.
A20: Demographics | B20: Maps Responses columns that hold demographics (e.g. region, age, organisation type) to short labels. Used to filter and segment results.
A21: Open Questions | B21: One row per free-text question. Points at a Responses column whose answers are free and open text.
A22: Multiple Choice Questions | B22: One row per multiple-choice question. Points at a Responses column whose answers come from a fixed list (e.g. Yes/No, Agree/Disagree, …).
A23: Hybrid Questions | B23: One row per question that has BOTH a multiple-choice part and a free-text 'why?' part — points at the two Responses columns that hold them.
A25: What good question text looks like
A26: IMPORTANT: the Question text is the title that Consult — and the AI model behind it — sees when analysing each response. It is the model's main signal for what was actually asked. If the question text is vague, truncated, or missing the framing the respondent saw, the model will misinterpret answers and the themes it generates will be off. Treat this column as the prompt you're giving the AI: give it enough context to understand the question on its own, without you in the room to explain.
A27: • | B27: Reads as a complete, standalone question — the AI model (and any analyst) should be able to understand what respondents were asked from this row alone.
A28: • | B28: Includes the preamble or framing that appeared with the question on the form (e.g. 'Considering the proposed boundary changes, …'). Without it, the model loses the topic the question is about.
A29: • | B29: Matches the wording on the Responses header reasonably closely (the label-similarity check flags large mismatches as 'To check').
A30: • | B30: Is a single question with just enough context — not a paragraph of background. Don't paste in policy notes or explanatory waffle that wasn't shown to respondents; that adds noise the model has to wade through.
A31: • | B31: No leading numbering like 'Q1.' / 'Question 3:' — put the number in the Question number column instead.
A33: Examples — Open Questions
B34: Example | C34: Why
A35: Good | B35: What role would you and/or your organisation play in achieving the proposed outcomes? | C35: Reads as a full, self-contained question. The AI knows it's asking about the respondent's role in delivering the proposal — so it can correctly group answers like 'we'd run training' under a 'role: training provider' theme.
A36: Bad | B36: role played | C36: Two words with no context. The model has no idea what role, in what, or whose. It can't tell whether 'we organised workshops' is on-topic or not, so themes will be generic and noisy.
B38: Example | C38: Why
A39: Good | B39: Considering the proposal in section 3, please explain the most important factors to achieving the proposed outcomes. | C39: Names the proposal being asked about and the type of answer expected (factors, not opinions). The model can anchor themes to 'enablers of the section 3 proposal'.
A40: Bad | B40: Section 3 — see attached policy paper for the full background and context, including the previous consultation responses from 2023, the impact assessment, and the equality screening. Free text. | C40: Mostly background admin that the respondent never saw. The actual question is buried (or missing). The model wastes its context budget on irrelevant framing.
A42: Examples — Multiple Choice Questions
B43: Example | C43: Why
A44: Good | B44: To what extent do you agree or disagree that the proposed councils are the right size to be efficient? | C44: Specifies the dimension being judged (size → efficiency) and the scale of answer. Free-text rationales attached to it can be themed against that specific claim.
A45: Bad | B45: Q3 size | C45: Just an internal reference. The model doesn't know what about size was being judged, what the scale was, or which proposal.
A47: Examples — Hybrid Questions
B48: Example | C48: Why
A49: Good | B49: Where do each of the proposed outcomes sit on a scale from very useful to not useful at all? Please explain your answer. | C49: Captures both halves of the hybrid in one sentence: the scale (very useful → not useful) and the prompt for free-text reasoning. The model can connect each rating with its rationale.
A50: Bad | B50: See attached. (open + closed combined) | C50: Tells the AI nothing — there's no attached document at analysis time. Themes will collapse across unrelated outcomes because the model can't tell them apart.
...

Sheet Active issues
A1: Active issues
A2: Errors: | B2: =SUMPRODUCT((Issues!E5:E3409<>"")*(Issues!D5:D3409="Error")) -> 0 | C2: To check: | D2: =SUMPRODUCT((Issues!E5:E3409<>"")*(Issues!D5:D3409="To check")) -> 0
A3: Errors MUST be fixed before running the consultation — they will stop the pipeline. "To check" items are heuristic flags; please review each one and confirm it's intentional (they may be fine). This sheet updates automatically as you edit the Demographics, Open, Closed and Hybrid sheets. See the Guide tab for what each sheet is for and what good questions look like. The 'My Notes' column on the right is the only editable column — use it to record what you checked.
A4: Sheet | B4: Cell | C4: Rule | D4: Severity | E4: Issue | F4: How to fix | G4: My Notes — provide a short description of what you checked here
A5: {=_xlfn._xlws.FILTER(Issues!A5:F3409,Issues!E5:E3409<>"","No outstanding issues — fill in the Demographics, Open, Closed and Hybrid sheets to begin.")} -> 0

Sheet Responses
A1: respondent_id | B1: Which region of the UK do you live in? | C1: Which age band are you in? | D1: What type of organisation are you responding on behalf of? | E1: Q1: To what extent do you support the proposal set out in chapter 3? | F1: Q1: Please explain the reasoning behind your level of support for the proposal. | G1: Q2: How important is this issue to you personally? | H1: Q2: Please explain why you rated the importance of this issue the way you did. | I1: Q3: Do you have any other suggestions or comments you would like to share with us? | J1: Q4: Would you recommend this approach to others working in a similar context?
A2: R0001 | B2: Scotland | C2: 65+ | D2: Charity | E2: Strongly agree | F2: The proposal is unclear and I am not sure what it would change. | H2: Without ringfenced funding none of this will be deliverable. | J2: Yes
A3: R0002 | B3: Scotland | C3: 25-34 | D3: Business | E3: Strongly agree | F3: Cost is the main concern — there should be more detail on funding. | G3: Medium | H3: Without ringfenced funding none of this will be deliverable. | J3: No
A4: R0003 | B4: Wales | C4: 35-44 | D4: Public sector | E4: Disagree | F4: I am worried about the impact on small businesses like mine. | G4: Low | H4: Digital-only delivery would exclude many of the people we support. | J4: Unsure
A5: R0004 | B5: East | C5: 25-34 | D5: Public sector | E5: Neutral | F5: More consultation with frontline staff is needed before deciding. | G5: Medium | H5: Existing schemes already cover most of this — avoid duplication. | I5: Set up a feedback channel that stays open after rollout. | J5: Unsure
A6: R0005 | B6: South | C6: 35-44 | D6: Charity | E6: Strongly agree | F6: I think this would help vulnerable groups in my community. | G6: Medium | H6: Without ringfenced funding none of this will be deliverable. | I6: Set up a feedback channel that stays open after rollout. | J6: No
A7: R0006 | B7: West | C7: 65+ | D7: Business | E7: Strongly disagree | F7: The timeline feels unrealistic given current resource pressures. | G7: Medium | H7: Without ringfenced funding none of this will be deliverable. | I7: Add a transitional protection period for current beneficiaries. | J7: Yes
A8: R0007 | B8: South | C8: 45-54 | D8: Public sector | E8: Disagree | F8: I think this would help vulnerable groups in my community. | G8: High | H8: It should be piloted in two or three regions first. | I8: Use independent evaluators to monitor early outcomes. | J8: No
A9: R0008 | C9: 65+ | D9: Business | E9: Agree | F9: The proposal is unclear and I am not sure what it would change. | G9: Medium | H9: It should be piloted in two or three regions first. | I9: Publish an equality impact assessment alongside the final policy. | J9: Yes
A10: R0009 | B10: Wales | C10: 18-24 | E10: Neutral | F10: I am worried about the impact on small businesses like mine. | G10: High | I10: Provide template materials in plain English and Welsh. | J10: Unsure
A11: R0010 | B11: South | C11: 55-64 | D11: Public sector | E11: Strongly disagree | F11: It aligns with what other countries are doing successfully. | G11: Medium | H11: Existing schemes already cover most of this — avoid duplication. | I11: Set up a feedback channel that stays open after rollout. | J11: Yes
A12: R0011 | C12: 55-64 | E12: Strongly agree | F12: I think this would help vulnerable groups in my community. | G12: High | H12: Digital-only delivery would exclude many of the people we support. | I12: Publish an equality impact assessment alongside the final policy. | J12: Unsure
A13: R0012 | B13: London | C13: 25-34 | D13: Public sector | E13: Strongly agree | F13: More consultation with frontline staff is needed before deciding. | G13: Medium | H13: Local authorities need clearer guidance and a longer lead-in time. | J13: No
A14: R0013 | B14: Wales | C14: 25-34 | D14: Public sector | E14: Agree | F14: It aligns with what other countries are doing successfully. | G14: High | I14: Use independent evaluators to monitor early outcomes. | J14: Yes
A15: R0014 | B15: Wales | C15: 25-34 | D15: Public sector | E15: Disagree | F15: Cost is the main concern — there should be more detail on funding. | G15: Medium | H15: Clear performance metrics and public reporting would help. | I15: Use independent evaluators to monitor early outcomes. | J15: Unsure
A16: R0015 | B16: West | C16: 35-44 | D16: Individual | E16: Strongly disagree | G16: Low | J16: Yes
A17: R0016 | B17: North | C17: 25-34 | D17: Charity | E17: Strongly agree | F17: The timeline feels unrealistic given current resource pressures. | G17: Low | H17: Digital-only delivery would exclude many of the people we support. | I17: Use independent evaluators to monitor early outcomes. | J17: No
A18: R0017 | B18: Scotland | C18: 45-54 | E18: Strongly disagree | G18: High | H18: Without ringfenced funding none of this will be deliverable. | I18: Add a transitional protection period for current beneficiaries. | J18: No
A19: R0018 | B19: West | C19: 65+ | D19: Individual | E19: Strongly disagree | F19: The proposal is unclear and I am not sure what it would change. | G19: High | H19: Local authorities need clearer guidance and a longer lead-in time. | J19: Unsure
A20: R0019 | B20: East | C20: 65+ | D20: Public sector | E20: Strongly agree | F20: The timeline feels unrealistic given current resource pressures. | H20: Without ringfenced funding none of this will be deliverable. | J20: No
A21: R0020 | B21: West | C21: 18-24 | D21: Charity | E21: Neutral | F21: Cost is the main concern — there should be more detail on funding. | G21: High | H21: Local authorities need clearer guidance and a longer lead-in time. | I21: Publish an equality impact assessment alongside the final policy. | J21: Unsure
A22: R0021 | B22: Wales | C22: 45-54 | D22: Charity | E22: Agree | F22: Cost is the main concern — there should be more detail on funding. | G22: High | H22: Digital-only delivery would exclude many of the people we support. | I22: Provide template materials in plain English and Welsh. | J22: Unsure
A23: R0022 | B23: East | C23: 65+ | D23: Individual | E23: Agree | F23: I welcome the focus on accessibility but it could go further. | G23: High | J23: Yes
A24: R0023 | B24: East | C24: 55-64 | D24: Business | E24: Strongly agree | F24: I am worried about the impact on small businesses like mine. | H24: It should be piloted in two or three regions first. | I24: Use independent evaluators to monitor early outcomes. | J24: No
A25: R0024 | B25: London | C25: 55-64 | D25: Individual | E25: Strongly agree | F25: It aligns with what other countries are doing successfully. | G25: High | H25: Digital-only delivery would exclude many of the people we support. | I25: Use independent evaluators to monitor early outcomes. | J25: Unsure
A26: R0025 | B26: London | C26: 45-54 | D26: Business | E26: Agree | F26: The timeline feels unrealistic given current resource pressures. | G26: High | H26: Digital-only delivery would exclude many of the people we support. | I26: Add a transitional protection period for current beneficiaries. | J26: Yes
A27: R0026 | B27: London | C27: 35-44 | D27: Public sector | E27: Strongly disagree | F27: Cost is the main concern — there should be more detail on funding. | G27: Medium | H27: Existing schemes already cover most of this — avoid duplication. | I27: Add a transitional protection period for current beneficiaries. | J27: Yes
A28: R0027 | B28: South | D28: Charity | E28: Strongly disagree | F28: The proposal is unclear and I am not sure what it would change. | G28: Low | H28: Existing schemes already cover most of this — avoid duplication. | I28: Provide template materials in plain English and Welsh. | J28: Yes
A29: R0028 | B29: North | C29: 18-24 | D29: Charity | E29: Strongly disagree | F29: It aligns with what other countries are doing successfully. | G29: High | H29: Clear performance metrics and public reporting would help. | I29: Set up a feedback channel that stays open after rollout. | J29: No
A30: R0029 | B30: Scotland | C30: 45-54 | D30: Public sector | E30: Disagree | F30: It aligns with what other countries are doing successfully. | G30: Medium | H30: It should be piloted in two or three regions first. | J30: Yes
A31: R0030 | B31: South | C31: 35-44 | D31: Individual | E31: Agree | F31: Cost is the main concern — there should be more detail on funding. | G31: High | H31: Digital-only delivery would exclude many of the people we support. | J31: No
A32: R0031 | B32: Wales | D32: Public sector | E32: Neutral | F32: The timeline feels unrealistic given current resource pressures. | G32: Medium | H32: Existing schemes already cover most of this — avoid duplication. | I32: Set up a feedback channel that stays open after rollout. | J32: No
A33: R0032 | B33: West | C33: 45-54 | D33: Public sector | E33: Disagree | F33: I think this would help vulnerable groups in my community. | G33: Low | J33: No
A34: R0033 | B34: East | C34: 25-34 | D34: Business | E34: Disagree | F34: The timeline feels unrealistic given current resource pressures. | G34: High | H34: Existing schemes already cover most of this — avoid duplication. | J34: Yes
A35: R0034 | C35: 18-24 | D35: Charity | E35: Strongly disagree | F35: Cost is the main concern — there should be more detail on funding. | G35: High | H35: Without ringfenced funding none of this will be deliverable. | I35: Engage charities that work directly with affected groups. | J35: Yes
A36: R0035 | B36: Scotland | C36: 25-34 | D36: Individual | E36: Neutral | F36: The timeline feels unrealistic given current resource pressures. | G36: Low | H36: It should be piloted in two or three regions first. | J36: Unsure
A37: R0036 | B37: Wales | C37: 18-24 | D37: Individual | E37: Disagree | F37: The proposal is unclear and I am not sure what it would change. | H37: Clear performance metrics and public reporting would help. | I37: Add a transitional protection period for current beneficiaries. | J37: No
A38: R0037 | B38: Wales | C38: 25-34 | D38: Business | E38: Strongly disagree | F38: I welcome the focus on accessibility but it could go further. | G38: Low | H38: Digital-only delivery would exclude many of the people we support. | J38: No
A39: R0038 | B39: West | C39: 65+ | D39: Individual | E39: Neutral | F39: It aligns with what other countries are doing successfully. | G39: Medium | H39: It should be piloted in two or three regions first. | I39: Engage charities that work directly with affected groups. | J39: Unsure
A40: R0039 | B40: North | C40: 45-54 | D40: Charity | E40: Disagree | G40: High | H40: Without ringfenced funding none of this will be deliverable. | I40: Set up a feedback channel that stays open after rollout. | J40: Unsure
...

Sheet Demographics
A1: Column letter (in Responses sheet) | B1: Demographics label
A2: B | B2: Region
A3: C | B3: Age band
A4: D | B4: Organisation type

Sheet Open Questions
A1: Column letter (in Responses sheet) | B1: Question number | C1: Question text (full wording shown to respondent)
A2: I | B2: 3 | C2: Do you have any other suggestions or comments?

Sheet Multiple Choice Questions
A1: Column letter (in Responses sheet) | B1: Question number | C1: Question text (full wording shown to respondent)
A2: J | B2: 4 | C2: Would you recommend this approach to others?

Sheet Hybrid Questions
A1: Free-text column letter (in Responses) | B1: Question number | C1: Question text (full wording shown to respondent) | D1: Multiple-choice column letter (in Responses)
A2: F | B2: 1 | C2: What is your level of support for the proposal, and why? | D2: E
A3: H | B3: 2 | C3: How important is this issue, and please explain. | D3: G

Sheet Issues
A1: Outstanding issues
A2: Outstanding issues: | B2: =SUMPRODUCT(--(E5:E3409<>"")) -> 0
A3: Source audit log — every (sheet, row, rule) combination. The Active issues sheet pulls only the rows where the Issue column is non-empty, via FILTER(). Hidden by default; unhide via right-click on a tab → Unhide if you need to inspect raw rules.
A4: Sheet | B4: Cell | C4: Rule | D4: Severity | E4: Issue | F4: How to fix
A5: Demographics | B5: A2 | C5: Column not in Responses | D5: Error | E5: =IF(AND('Demographics'!$A$2<>"",IFERROR(INDEX(Responses!$A$1:$XFD$1,1,CHOOSE(LEN(TRIM('Demographics'!$A$2)),CODE(TRIM('Demographics'!$A$2))-64,(CODE(LEFT(TRIM('Demographics'!$A$2),1))-64)*26+(CODE(RIGHT(TRIM('Demographics'!$A$2),1))-64),(CODE(LEFT(TRIM('Demographics'!$A$2),1))-64)*676+(CODE(MID(TRIM('Demographics'!$A$2),2,1))-64)*26+(CODE(RIGHT(TRIM('Demographics'!$A$2),1))-64))),"")=""),"Column '"&'Demographics'!$A$2&"' has no header on the Responses sheet, so there's nothing for Themefinder to read.","") -> 0 | F5: Check for a typo in the column letter, or add a header (and the answers) into that column on Responses.
A6: Demographics | B6: A3 | C6: Column not in Responses | D6: Error | E6: =IF(AND('Demographics'!$A$3<>"",IFERROR(INDEX(Responses!$A$1:$XFD$1,1,CHOOSE(LEN(TRIM('Demographics'!$A$3)),CODE(TRIM('Demographics'!$A$3))-64,(CODE(LEFT(TRIM('Demographics'!$A$3),1))-64)*26+(CODE(RIGHT(TRIM('Demographics'!$A$3),1))-64),(CODE(LEFT(TRIM('Demographics'!$A$3),1))-64)*676+(CODE(MID(TRIM('Demographics'!$A$3),2,1))-64)*26+(CODE(RIGHT(TRIM('Demographics'!$A$3),1))-64))),"")=""),"Column '"&'Demographics'!$A$3&"' has no header on the Responses sheet, so there's nothing for Themefinder to read.","") -> 0 | F6: Check for a typo in the column letter, or add a header (and the answers) into that column on Responses.
A7: Demographics | B7: A4 | C7: Column not in Responses | D7: Error | E7: =IF(AND('Demographics'!$A$4<>"",IFERROR(INDEX(Responses!$A$1:$XFD$1,1,CHOOSE(LEN(TRIM('Demographics'!$A$4)),CODE(TRIM('Demographics'!$A$4))-64,(CODE(LEFT(TRIM('Demographics'!$A$4),1))-64)*26+(CODE(RIGHT(TRIM('Demographics'!$A$4),1))-64),(CODE(LEFT(TRIM('Demographics'!$A$4),1))-64)*676+(CODE(MID(TRIM('Demographics'!$A$4),2,1))-64)*26+(CODE(RIGHT(TRIM('Demographics'!$A$4),1))-64))),"")=""),"Column '"&'Demographics'!$A$4&"' has no header on the Responses sheet, so there's nothing for Themefinder to read.","") -> 0 | F7: Check for a typo in the column letter, or add a header (and the answers) into that column on Responses.
A8: Demographics | B8: A5 | C8: Column not in Responses | D8: Error | E8: =IF(AND('Demographics'!$A$5<>"",IFERROR(INDEX(Responses!$A$1:$XFD$1,1,CHOOSE(LEN(TRIM('Demographics'!$A$5)),CODE(TRIM('Demographics'!$A$5))-64,(CODE(LEFT(TRIM('Demographics'!$A$5),1))-64)*26+(CODE(RIGHT(TRIM('Demographics'!$A$5),1))-64),(CODE(LEFT(TRIM('Demographics'!$A$5),1))-64)*676+(CODE(MID(TRIM('Demographics'!$A$5),2,1))-64)*26+(CODE(RIGHT(TRIM('Demographics'!$A$5),1))-64))),"")=""),"Column '"&'Demographics'!$A$5&"' has no header on the Responses sheet, so there's nothing for Themefinder to read.","") -> 0 | F8: Check for a typo in the column letter, or add a header (and the answers) into that column on Responses.
A9: Demographics | B9: A6 | C9: Column not in Responses | D9: Error | E9: =IF(AND('Demographics'!$A$6<>"",IFERROR(INDEX(Responses!$A$1:$XFD$1,1,CHOOSE(LEN(TRIM('Demographics'!$A$6)),CODE(TRIM('Demographics'!$A$6))-64,(CODE(LEFT(TRIM('Demographics'!$A$6),1))-64)*26+(CODE(RIGHT(TRIM('Demographics'!$A$6),1))-64),(CODE(LEFT(TRIM('Demographics'!$A$6),1))-64)*676+(CODE(MID(TRIM('Demographics'!$A$6),2,1))-64)*26+(CODE(RIGHT(TRIM('Demographics'!$A$6),1))-64))),"")=""),"Column '"&'Demographics'!$A$6&"' has no header on the Responses sheet, so there's nothing for Themefinder to read.","") -> 0 | F9: Check for a typo in the column letter, or add a header (and the answers) into that column on Responses.
A10: Demographics | B10: A7 | C10: Column not in Responses | D10: Error | E10: =IF(AND('Demographics'!$A$7<>"",IFERROR(INDEX(Responses!$A$1:$XFD$1,1,CHOOSE(LEN(TRIM('Demographics'!$A$7)),CODE(TRIM('Demographics'!$A$7))-64,(CODE(LEFT(TRIM('Demographics'!$A$7),1))-64)*26+(CODE(RIGHT(TRIM('Demographics'!$A$7),1))-64),(CODE(LEFT(TRIM('Demographics'!$A$7),1))-64)*676+(CODE(MID(TRIM('Demographics'!$A$7),2,1))-64)*26+(CODE(RIGHT(TRIM('Demographics'!$A$7),1))-64))),"")=""),"Column '"&'Demographics'!$A$7&"' has no header on the Responses sheet, so there's nothing for Themefinder to read.","") -> 0 | F10: Check for a typo in the column letter, or add a header (and the answers) into that column on Responses.
A11: Demographics | B11: A8 | C11: Column not in Responses | D11: Error | E11: =IF(AND('Demographics'!$A$8<>"",IFERROR(INDEX(Responses!$A$1:$XFD$1,1,CHOOSE(LEN(TRIM('Demographics'!$A$8)),CODE(TRIM('Demographics'!$A$8))-64,(CODE(LEFT(TRIM('Demographics'!$A$8),1))-64)*26+(CODE(RIGHT(TRIM('Demographics'!$A$8),1))-64),(CODE(LEFT(TRIM('Demographics'!$A$8),1))-64)*676+(CODE(MID(TRIM('Demographics'!$A$8),2,1))-64)*26+(CODE(RIGHT(TRIM('Demographics'!$A$8),1))-64))),"")=""),"Column '"&'Demographics'!$A$8&"' has no header on the Responses sheet, so there's nothing for Themefinder to read.","") -> 0 | F11: Check for a typo in the column letter, or add a header (and the answers) into that column on Responses.
A12: Demographics | B12: A9 | C12: Column not in Responses | D12: Error | E12: =IF(AND('Demographics'!$A$9<>"",IFERROR(INDEX(Responses!$A$1:$XFD$1,1,CHOOSE(LEN(TRIM('Demographics'!$A$9)),CODE(TRIM('Demographics'!$A$9))-64,(CODE(LEFT(TRIM('Demographics'!$A$9),1))-64)*26+(CODE(RIGHT(TRIM('Demographics'!$A$9),1))-64),(CODE(LEFT(TRIM('Demographics'!$A$9),1))-64)*676+(CODE(MID(TRIM('Demographics'!$A$9),2,1))-64)*26+(CODE(RIGHT(TRIM('Demographics'!$A$9),1))-64))),"")=""),"Column '"&'Demographics'!$A$9&"' has no header on the Responses sheet, so there's nothing for Themefinder to read.","") -> 0 | F12: Check for a typo in the column letter, or add a header (and the answers) into that column on Responses.
A13: Demographics | B13: A10 | C13: Column not in Responses | D13: Error | E13: =IF(AND('Demographics'!$A$10<>"",IFERROR(INDEX(Responses!$A$1:$XFD$1,1,CHOOSE(LEN(TRIM('Demographics'!$A$10)),CODE(TRIM('Demographics'!$A$10))-64,(CODE(LEFT(TRIM('Demographics'!$A$10),1))-64)*26+(CODE(RIGHT(TRIM('Demographics'!$A$10),1))-64),(CODE(LEFT(TRIM('Demographics'!$A$10),1))-64)*676+(CODE(MID(TRIM('Demographics'!$A$10),2,1))-64)*26+(CODE(RIGHT(TRIM('Demographics'!$A$10),1))-64))),"")=""),"Column '"&'Demographics'!$A$10&"' has no header on the Responses sheet, so there's nothing for Themefinder to read.","") -> 0 | F13: Check for a typo in the column letter, or add a header (and the answers) into that column on Responses.
A14: Demographics | B14: A11 | C14: Column not in Responses | D14: Error | E14: =IF(AND('Demographics'!$A$11<>"",IFERROR(INDEX(Responses!$A$1:$XFD$1,1,CHOOSE(LEN(TRIM('Demographics'!$A$11)),CODE(TRIM('Demographics'!$A$11))-64,(CODE(LEFT(TRIM('Demographics'!$A$11),1))-64)*26+(CODE(RIGHT(TRIM('Demographics'!$A$11),1))-64),(CODE(LEFT(TRIM('Demographics'!$A$11),1))-64)*676+(CODE(MID(TRIM('Demographics'!$A$11),2,1))-64)*26+(CODE(RIGHT(TRIM('Demographics'!$A$11),1))-64))),"")=""),"Column '"&'Demographics'!$A$11&"' has no header on the Responses sheet, so there's nothing for Themefinder to read.","") -> 0 | F14: Check for a typo in the column letter, or add a header (and the answers) into that column on Responses.
A15: Demographics | B15: A12 | C15: Column not in Responses | D15: Error | E15: =IF(AND('Demographics'!$A$12<>"",IFERROR(INDEX(Responses!$A$1:$XFD$1,1,CHOOSE(LEN(TRIM('Demographics'!$A$12)),CODE(TRIM('Demographics'!$A$12))-64,(CODE(LEFT(TRIM('Demographics'!$A$12),1))-64)*26+(CODE(RIGHT(TRIM('Demographics'!$A$12),1))-64),(CODE(LEFT(TRIM('Demographics'!$A$12),1))-64)*676+(CODE(MID(TRIM('Demographics'!$A$12),2,1))-64)*26+(CODE(RIGHT(TRIM('Demographics'!$A$12),1))-64))),"")=""),"Column '"&'Demographics'!$A$12&"' has no header on the Responses sheet, so there's nothing for Themefinder to read.","") -> 0 | F15: Check for a typo in the column letter, or add a header (and the answers) into that column on Responses.
A16: Demographics | B16: A13 | C16: Column not in Responses | D16: Error | E16: =IF(AND('Demographics'!$A$13<>"",IFERROR(INDEX(Responses!$A$1:$XFD$1,1,CHOOSE(LEN(TRIM('Demographics'!$A$13)),CODE(TRIM('Demographics'!$A$13))-64,(CODE(LEFT(TRIM('Demographics'!$A$13),1))-64)*26+(CODE(RIGHT(TRIM('Demographics'!$A$13),1))-64),(CODE(LEFT(TRIM('Demographics'!$A$13),1))-64)*676+(CODE(MID(TRIM('Demographics'!$A$13),2,1))-64)*26+(CODE(RIGHT(TRIM('Demographics'!$A$13),1))-64))),"")=""),"Column '"&'Demographics'!$A$13&"' has no header on the Responses sheet, so there's nothing for Themefinder to read.","") -> 0 | F16: Check for a typo in the column letter, or add a header (and the answers) into that column on Responses.
A17: Demographics | B17: A14 | C17: Column not in Responses | D17: Error | E17: =IF(AND('Demographics'!$A$14<>"",IFERROR(INDEX(Responses!$A$1:$XFD$1,1,CHOOSE(LEN(TRIM('Demographics'!$A$14)),CODE(TRIM('Demographics'!$A$14))-64,(CODE(LEFT(TRIM('Demographics'!$A$14),1))-64)*26+(CODE(RIGHT(TRIM('Demographics'!$A$14),1))-64),(CODE(LEFT(TRIM('Demographics'!$A$14),1))-64)*676+(CODE(MID(TRIM('Demographics'!$A$14),2,1))-64)*26+(CODE(RIGHT(TRIM('Demographics'!$A$14),1))-64))),"")=""),"Column '"&'Demographics'!$A$14&"' has no header on the Responses sheet, so there's nothing for Themefinder to read.","") -> 0 | F17: Check for a typo in the column letter, or add a header (and the answers) into that column on Responses.
A18: Demographics | B18: A15 | C18: Column not in Responses | D18: Error | E18: =IF(AND('Demographics'!$A$15<>"",IFERROR(INDEX(Responses!$A$1:$XFD$1,1,CHOOSE(LEN(TRIM('Demographics'!$A$15)),CODE(TRIM('Demographics'!$A$15))-64,(CODE(LEFT(TRIM('Demographics'!$A$15),1))-64)*26+(CODE(RIGHT(TRIM('Demographics'!$A$15),1))-64),(CODE(LEFT(TRIM('Demographics'!$A$15),1))-64)*676+(CODE(MID(TRIM('Demographics'!$A$15),2,1))-64)*26+(CODE(RIGHT(TRIM('Demographics'!$A$15),1))-64))),"")=""),"Column '"&'Demographics'!$A$15&"' has no header on the Responses sheet, so there's nothing for Themefinder to read.","") -> 0 | F18: Check for a typo in the column letter, or add a header (and the answers) into that column on Responses.
A19: Demographics | B19: A16 | C19: Column not in Responses | D19: Error | E19: =IF(AND('Demographics'!$A$16<>"",IFERROR(INDEX(Responses!$A$1:$XFD$1,1,CHOOSE(LEN(TRIM('Demographics'!$A$16)),CODE(TRIM('Demographics'!$A$16))-64,(CODE(LEFT(TRIM('Demographics'!$A$16),1))-64)*26+(CODE(RIGHT(TRIM('Demographics'!$A$16),1))-64),(CODE(LEFT(TRIM('Demographics'!$A$16),1))-64)*676+(CODE(MID(TRIM('Demographics'!$A$16),2,1))-64)*26+(CODE(RIGHT(TRIM('Demographics'!$A$16),1))-64))),"")=""),"Column '"&'Demographics'!$A$16&"' has no header on the Responses sheet, so there's nothing for Themefinder to read.","") -> 0 | F19: Check for a typo in the column letter, or add a header (and the answers) into that column on Responses.
A20: Demographics | B20: A17 | C20: Column not in Responses | D20: Error | E20: =IF(AND('Demographics'!$A$17<>"",IFERROR(INDEX(Responses!$A$1:$XFD$1,1,CHOOSE(LEN(TRIM('Demographics'!$A$17)),CODE(TRIM('Demographics'!$A$17))-64,(CODE(LEFT(TRIM('Demographics'!$A$17),1))-64)*26+(CODE(RIGHT(TRIM('Demographics'!$A$17),1))-64),(CODE(LEFT(TRIM('Demographics'!$A$17),1))-64)*676+(CODE(MID(TRIM('Demographics'!$A$17),2,1))-64)*26+(CODE(RIGHT(TRIM('Demographics'!$A$17),1))-64))),"")=""),"Column '"&'Demographics'!$A$17&"' has no header on the Responses sheet, so there's nothing for Themefinder to read.","") -> 0 | F20: Check for a typo in the column letter, or add a header (and the answers) into that column on Responses.
A21: Demographics | B21: A18 | C21: Column not in Responses | D21: Error | E21: =IF(AND('Demographics'!$A$18<>"",IFERROR(INDEX(Responses!$A$1:$XFD$1,1,CHOOSE(LEN(TRIM('Demographics'!$A$18)),CODE(TRIM('Demographics'!$A$18))-64,(CODE(LEFT(TRIM('Demographics'!$A$18),1))-64)*26+(CODE(RIGHT(TRIM('Demographics'!$A$18),1))-64),(CODE(LEFT(TRIM('Demographics'!$A$18),1))-64)*676+(CODE(MID(TRIM('Demographics'!$A$18),2,1))-64)*26+(CODE(RIGHT(TRIM('Demographics'!$A$18),1))-64))),"")=""),"Column '"&'Demographics'!$A$18&"' has no header on the Responses sheet, so there's nothing for Themefinder to read.","") -> 0 | F21: Check for a typo in the column letter, or add a header (and the answers) into that column on Responses.
A22: Demographics | B22: A19 | C22: Column not in Responses | D22: Error | E22: =IF(AND('Demographics'!$A$19<>"",IFERROR(INDEX(Responses!$A$1:$XFD$1,1,CHOOSE(LEN(TRIM('Demographics'!$A$19)),CODE(TRIM('Demographics'!$A$19))-64,(CODE(LEFT(TRIM('Demographics'!$A$19),1))-64)*26+(CODE(RIGHT(TRIM('Demographics'!$A$19),1))-64),(CODE(LEFT(TRIM('Demographics'!$A$19),1))-64)*676+(CODE(MID(TRIM('Demographics'!$A$19),2,1))-64)*26+(CODE(RIGHT(TRIM('Demographics'!$A$19),1))-64))),"")=""),"Column '"&'Demographics'!$A$19&"' has no header on the Responses sheet, so there's nothing for Themefinder to read.","") -> 0 | F22: Check for a typo in the column letter, or add a header (and the answers) into that column on Responses.
A23: Demographics | B23: A20 | C23: Column not in Responses | D23: Error | E23: =IF(AND('Demographics'!$A$20<>"",IFERROR(INDEX(Responses!$A$1:$XFD$1,1,CHOOSE(LEN(TRIM('Demographics'!$A$20)),CODE(TRIM('Demographics'!$A$20))-64,(CODE(LEFT(TRIM('Demographics'!$A$20),1))-64)*26+(CODE(RIGHT(TRIM('Demographics'!$A$20),1))-64),(CODE(LEFT(TRIM('Demographics'!$A$20),1))-64)*676+(CODE(MID(TRIM('Demographics'!$A$20),2,1))-64)*26+(CODE(RIGHT(TRIM('Demographics'!$A$20),1))-64))),"")=""),"Column '"&'Demographics'!$A$20&"' has no header on the Responses sheet, so there's nothing for Themefinder to read.","") -> 0 | F23: Check for a typo in the column letter, or add a header (and the answers) into that column on Responses.
A24: Demographics | B24: A21 | C24: Column not in Responses | D24: Error | E24: =IF(AND('Demographics'!$A$21<>"",IFERROR(INDEX(Responses!$A$1:$XFD$1,1,CHOOSE(LEN(TRIM('Demographics'!$A$21)),CODE(TRIM('Demographics'!$A$21))-64,(CODE(LEFT(TRIM('Demographics'!$A$21),1))-64)*26+(CODE(RIGHT(TRIM('Demographics'!$A$21),1))-64),(CODE(LEFT(TRIM('Demographics'!$A$21),1))-64)*676+(CODE(MID(TRIM('Demographics'!$A$21),2,1))-64)*26+(CODE(RIGHT(TRIM('Demographics'!$A$21),1))-64))),"")=""),"Column '"&'Demographics'!$A$21&"' has no header on the Responses sheet, so there's nothing for Themefinder to read.","") -> 0 | F24: Check for a typo in the column letter, or add a header (and the answers) into that column on Responses.
A25: Demographics | B25: A22 | C25: Column not in Responses | D25: Error | E25: =IF(AND('Demographics'!$A$22<>"",IFERROR(INDEX(Responses!$A$1:$XFD$1,1,CHOOSE(LEN(TRIM('Demographics'!$A$22)),CODE(TRIM('Demographics'!$A$22))-64,(CODE(LEFT(TRIM('Demographics'!$A$22),1))-64)*26+(CODE(RIGHT(TRIM('Demographics'!$A$22),1))-64),(CODE(LEFT(TRIM('Demographics'!$A$22),1))-64)*676+(CODE(MID(TRIM('Demographics'!$A$22),2,1))-64)*26+(CODE(RIGHT(TRIM('Demographics'!$A$22),1))-64))),"")=""),"Column '"&'Demographics'!$A$22&"' has no header on the Responses sheet, so there's nothing for Themefinder to read.","") -> 0 | F25: Check for a typo in the column letter, or add a header (and the answers) into that column on Responses.
A26: Demographics | B26: A23 | C26: Column not in Responses | D26: Error | E26: =IF(AND('Demographics'!$A$23<>"",IFERROR(INDEX(Responses!$A$1:$XFD$1,1,CHOOSE(LEN(TRIM('Demographics'!$A$23)),CODE(TRIM('Demographics'!$A$23))-64,(CODE(LEFT(TRIM('Demographics'!$A$23),1))-64)*26+(CODE(RIGHT(TRIM('Demographics'!$A$23),1))-64),(CODE(LEFT(TRIM('Demographics'!$A$23),1))-64)*676+(CODE(MID(TRIM('Demographics'!$A$23),2,1))-64)*26+(CODE(RIGHT(TRIM('Demographics'!$A$23),1))-64))),"")=""),"Column '"&'Demographics'!$A$23&"' has no header on the Responses sheet, so there's nothing for Themefinder to read.","") -> 0 | F26: Check for a typo in the column letter, or add a header (and the answers) into that column on Responses.
A27: Demographics | B27: A24 | C27: Column not in Responses | D27: Error | E27: =IF(AND('Demographics'!$A$24<>"",IFERROR(INDEX(Responses!$A$1:$XFD$1,1,CHOOSE(LEN(TRIM('Demographics'!$A$24)),CODE(TRIM('Demographics'!$A$24))-64,(CODE(LEFT(TRIM('Demographics'!$A$24),1))-64)*26+(CODE(RIGHT(TRIM('Demographics'!$A$24),1))-64),(CODE(LEFT(TRIM('Demographics'!$A$24),1))-64)*676+(CODE(MID(TRIM('Demographics'!$A$24),2,1))-64)*26+(CODE(RIGHT(TRIM('Demographics'!$A$24),1))-64))),"")=""),"Column '"&'Demographics'!$A$24&"' has no header on the Responses sheet, so there's nothing for Themefinder to read.","") -> 0 | F27: Check for a typo in the column letter, or add a header (and the answers) into that column on Responses.
A28: Demographics | B28: A25 | C28: Column not in Responses | D28: Error | E28: =IF(AND('Demographics'!$A$25<>"",IFERROR(INDEX(Responses!$A$1:$XFD$1,1,CHOOSE(LEN(TRIM('Demographics'!$A$25)),CODE(TRIM('Demographics'!$A$25))-64,(CODE(LEFT(TRIM('Demographics'!$A$25),1))-64)*26+(CODE(RIGHT(TRIM('Demographics'!$A$25),1))-64),(CODE(LEFT(TRIM('Demographics'!$A$25),1))-64)*676+(CODE(MID(TRIM('Demographics'!$A$25),2,1))-64)*26+(CODE(RIGHT(TRIM('Demographics'!$A$25),1))-64))),"")=""),"Column '"&'Demographics'!$A$25&"' has no header on the Responses sheet, so there's nothing for Themefinder to read.","") -> 0 | F28: Check for a typo in the column letter, or add a header (and the answers) into that column on Responses.
A29: Demographics | B29: A26 | C29: Column not in Responses | D29: Error | E29: =IF(AND('Demographics'!$A$26<>"",IFERROR(INDEX(Responses!$A$1:$XFD$1,1,CHOOSE(LEN(TRIM('Demographics'!$A$26)),CODE(TRIM('Demographics'!$A$26))-64,(CODE(LEFT(TRIM('Demographics'!$A$26),1))-64)*26+(CODE(RIGHT(TRIM('Demographics'!$A$26),1))-64),(CODE(LEFT(TRIM('Demographics'!$A$26),1))-64)*676+(CODE(MID(TRIM('Demographics'!$A$26),2,1))-64)*26+(CODE(RIGHT(TRIM('Demographics'!$A$26),1))-64))),"")=""),"Column '"&'Demographics'!$A$26&"' has no header on the Responses sheet, so there's nothing for Themefinder to read.","") -> 0 | F29: Check for a typo in the column letter, or add a header (and the answers) into that column on Responses.
A30: Demographics | B30: A27 | C30: Column not in Responses | D30: Error | E30: =IF(AND('Demographics'!$A$27<>"",IFERROR(INDEX(Responses!$A$1:$XFD$1,1,CHOOSE(LEN(TRIM('Demographics'!$A$27)),CODE(TRIM('Demographics'!$A$27))-64,(CODE(LEFT(TRIM('Demographics'!$A$27),1))-64)*26+(CODE(RIGHT(TRIM('Demographics'!$A$27),1))-64),(CODE(LEFT(TRIM('Demographics'!$A$27),1))-64)*676+(CODE(MID(TRIM('Demographics'!$A$27),2,1))-64)*26+(CODE(RIGHT(TRIM('Demographics'!$A$27),1))-64))),"")=""),"Column '"&'Demographics'!$A$27&"' has no header on the Responses sheet, so there's nothing for Themefinder to read.","") -> 0 | F30: Check for a typo in the column letter, or add a header (and the answers) into that column on Responses.
A31: Demographics | B31: A28 | C31: Column not in Responses | D31: Error | E31: =IF(AND('Demographics'!$A$28<>"",IFERROR(INDEX(Responses!$A$1:$XFD$1,1,CHOOSE(LEN(TRIM('Demographics'!$A$28)),CODE(TRIM('Demographics'!$A$28))-64,(CODE(LEFT(TRIM('Demographics'!$A$28),1))-64)*26+(CODE(RIGHT(TRIM('Demographics'!$A$28),1))-64),(CODE(LEFT(TRIM('Demographics'!$A$28),1))-64)*676+(CODE(MID(TRIM('Demographics'!$A$28),2,1))-64)*26+(CODE(RIGHT(TRIM('Demographics'!$A$28),1))-64))),"")=""),"Column '"&'Demographics'!$A$28&"' has no header on the Responses sheet, so there's nothing for Themefinder to read.","") -> 0 | F31: Check for a typo in the column letter, or add a header (and the answers) into that column on Responses.
A32: Demographics | B32: A29 | C32: Column not in Responses | D32: Error | E32: =IF(AND('Demographics'!$A$29<>"",IFERROR(INDEX(Responses!$A$1:$XFD$1,1,CHOOSE(LEN(TRIM('Demographics'!$A$29)),CODE(TRIM('Demographics'!$A$29))-64,(CODE(LEFT(TRIM('Demographics'!$A$29),1))-64)*26+(CODE(RIGHT(TRIM('Demographics'!$A$29),1))-64),(CODE(LEFT(TRIM('Demographics'!$A$29),1))-64)*676+(CODE(MID(TRIM('Demographics'!$A$29),2,1))-64)*26+(CODE(RIGHT(TRIM('Demographics'!$A$29),1))-64))),"")=""),"Column '"&'Demographics'!$A$29&"' has no header on the Responses sheet, so there's nothing for Themefinder to read.","") -> 0 | F32: Check for a typo in the column letter, or add a header (and the answers) into that column on Responses.
A33: Demographics | B33: A30 | C33: Column not in Responses | D33: Error | E33: =IF(AND('Demographics'!$A$30<>"",IFERROR(INDEX(Responses!$A$1:$XFD$1,1,CHOOSE(LEN(TRIM('Demographics'!$A$30)),CODE(TRIM('Demographics'!$A$30))-64,(CODE(LEFT(TRIM('Demographics'!$A$30),1))-64)*26+(CODE(RIGHT(TRIM('Demographics'!$A$30),1))-64),(CODE(LEFT(TRIM('Demographics'!$A$30),1))-64)*676+(CODE(MID(TRIM('Demographics'!$A$30),2,1))-64)*26+(CODE(RIGHT(TRIM('Demographics'!$A$30),1))-64))),"")=""),"Column '"&'Demographics'!$A$30&"' has no header on the Responses sheet, so there's nothing for Themefinder to read.","") -> 0 | F33: Check for a typo in the column letter, or add a header (and the answers) into that column on Responses.
A34: Demographics | B34: A31 | C34: Column not in Responses | D34: Error | E34: =IF(AND('Demographics'!$A$31<>"",IFERROR(INDEX(Responses!$A$1:$XFD$1,1,CHOOSE(LEN(TRIM('Demographics'!$A$31)),CODE(TRIM('Demographics'!$A$31))-64,(CODE(LEFT(TRIM('Demographics'!$A$31),1))-64)*26+(CODE(RIGHT(TRIM('Demographics'!$A$31),1))-64),(CODE(LEFT(TRIM('Demographics'!$A$31),1))-64)*676+(CODE(MID(TRIM('Demographics'!$A$31),2,1))-64)*26+(CODE(RIGHT(TRIM('Demographics'!$A$31),1))-64))),"")=""),"Column '"&'Demographics'!$A$31&"' has no header on the Responses sheet, so there's nothing for Themefinder to read.","") -> 0 | F34: Check for a typo in the column letter, or add a header (and the answers) into that column on Responses.
A35: Demographics | B35: A32 | C35: Column not in Responses | D35: Error | E35: =IF(AND('Demographics'!$A$32<>"",IFERROR(INDEX(Responses!$A$1:$XFD$1,1,CHOOSE(LEN(TRIM('Demographics'!$A$32)),CODE(TRIM('Demographics'!$A$32))-64,(CODE(LEFT(TRIM('Demographics'!$A$32),1))-64)*26+(CODE(RIGHT(TRIM('Demographics'!$A$32),1))-64),(CODE(LEFT(TRIM('Demographics'!$A$32),1))-64)*676+(CODE(MID(TRIM('Demographics'!$A$32),2,1))-64)*26+(CODE(RIGHT(TRIM('Demographics'!$A$32),1))-64))),"")=""),"Column '"&'Demographics'!$A$32&"' has no header on the Responses sheet, so there's nothing for Themefinder to read.","") -> 0 | F35: Check for a typo in the column letter, or add a header (and the answers) into that column on Responses.
A36: Demographics | B36: A33 | C36: Column not in Responses | D36: Error | E36: =IF(AND('Demographics'!$A$33<>"",IFERROR(INDEX(Responses!$A$1:$XFD$1,1,CHOOSE(LEN(TRIM('Demographics'!$A$33)),CODE(TRIM('Demographics'!$A$33))-64,(CODE(LEFT(TRIM('Demographics'!$A$33),1))-64)*26+(CODE(RIGHT(TRIM('Demographics'!$A$33),1))-64),(CODE(LEFT(TRIM('Demographics'!$A$33),1))-64)*676+(CODE(MID(TRIM('Demographics'!$A$33),2,1))-64)*26+(CODE(RIGHT(TRIM('Demographics'!$A$33),1))-64))),"")=""),"Column '"&'Demographics'!$A$33&"' has no header on the Responses sheet, so there's nothing for Themefinder to read.","") -> 0 | F36: Check for a typo in the column letter, or add a header (and the answers) into that column on Responses.
A37: Demographics | B37: A34 | C37: Column not in Responses | D37: Error | E37: =IF(AND('Demographics'!$A$34<>"",IFERROR(INDEX(Responses!$A$1:$XFD$1,1,CHOOSE(LEN(TRIM('Demographics'!$A$34)),CODE(TRIM('Demographics'!$A$34))-64,(CODE(LEFT(TRIM('Demographics'!$A$34),1))-64)*26+(CODE(RIGHT(TRIM('Demographics'!$A$34),1))-64),(CODE(LEFT(TRIM('Demographics'!$A$34),1))-64)*676+(CODE(MID(TRIM('Demographics'!$A$34),2,1))-64)*26+(CODE(RIGHT(TRIM('Demographics'!$A$34),1))-64))),"")=""),"Column '"&'Demographics'!$A$34&"' has no header on the Responses sheet, so there's nothing for Themefinder to read.","") -> 0 | F37: Check for a typo in the column letter, or add a header (and the answers) into that column on Responses.
A38: Demographics | B38: A35 | C38: Column not in Responses | D38: Error | E38: =IF(AND('Demographics'!$A$35<>"",IFERROR(INDEX(Responses!$A$1:$XFD$1,1,CHOOSE(LEN(TRIM('Demographics'!$A$35)),CODE(TRIM('Demographics'!$A$35))-64,(CODE(LEFT(TRIM('Demographics'!$A$35),1))-64)*26+(CODE(RIGHT(TRIM('Demographics'!$A$35),1))-64),(CODE(LEFT(TRIM('Demographics'!$A$35),1))-64)*676+(CODE(MID(TRIM('Demographics'!$A$35),2,1))-64)*26+(CODE(RIGHT(TRIM('Demographics'!$A$35),1))-64))),"")=""),"Column '"&'Demographics'!$A$35&"' has no header on the Responses sheet, so there's nothing for Themefinder to read.","") -> 0 | F38: Check for a typo in the column letter, or add a header (and the answers) into that column on Responses.
A39: Demographics | B39: A36 | C39: Column not in Responses | D39: Error | E39: =IF(AND('Demographics'!$A$36<>"",IFERROR(INDEX(Responses!$A$1:$XFD$1,1,CHOOSE(LEN(TRIM('Demographics'!$A$36)),CODE(TRIM('Demographics'!$A$36))-64,(CODE(LEFT(TRIM('Demographics'!$A$36),1))-64)*26+(CODE(RIGHT(TRIM('Demographics'!$A$36),1))-64),(CODE(LEFT(TRIM('Demographics'!$A$36),1))-64)*676+(CODE(MID(TRIM('Demographics'!$A$36),2,1))-64)*26+(CODE(RIGHT(TRIM('Demographics'!$A$36),1))-64))),"")=""),"Column '"&'Demographics'!$A$36&"' has no header on the Responses sheet, so there's nothing for Themefinder to read.","") -> 0 | F39: Check for a typo in the column letter, or add a header (and the answers) into that column on Responses.
A40: Demographics | B40: A37 | C40: Column not in Responses | D40: Error | E40: =IF(AND('Demographics'!$A$37<>"",IFERROR(INDEX(Responses!$A$1:$XFD$1,1,CHOOSE(LEN(TRIM('Demographics'!$A$37)),CODE(TRIM('Demographics'!$A$37))-64,(CODE(LEFT(TRIM('Demographics'!$A$37),1))-64)*26+(CODE(RIGHT(TRIM('Demographics'!$A$37),1))-64),(CODE(LEFT(TRIM('Demographics'!$A$37),1))-64)*676+(CODE(MID(TRIM('Demographics'!$A$37),2,1))-64)*26+(CODE(RIGHT(TRIM('Demographics'!$A$37),1))-64))),"")=""),"Column '"&'Demographics'!$A$37&"' has no header on the Responses sheet, so there's nothing for Themefinder to read.","") -> 0 | F40: Check for a typo in the column letter, or add a header (and the answers) into that column on Responses.
...

Sheet _helpers
A1: =IFERROR(SUMPRODUCT((Responses!A2:A8000<>"")/COUNTIF(Responses!A2:A8000,Responses!A2:A8000&""))/COUNTA(Responses!A2:A8000),0) -> 0 | B1: =IFERROR(SUMPRODUCT((Responses!B2:B8000<>"")/COUNTIF(Responses!B2:B8000,Responses!B2:B8000&""))/COUNTA(Responses!B2:B8000),0) -> 0 | C1: =IFERROR(SUMPRODUCT((Responses!C2:C8000<>"")/COUNTIF(Responses!C2:C8000,Responses!C2:C8000&""))/COUNTA(Responses!C2:C8000),0) -> 0 | D1: =IFERROR(SUMPRODUCT((Responses!D2:D8000<>"")/COUNTIF(Responses!D2:D8000,Responses!D2:D8000&""))/COUNTA(Responses!D2:D8000),0) -> 0 | E1: =IFERROR(SUMPRODUCT((Responses!E2:E8000<>"")/COUNTIF(Responses!E2:E8000,Responses!E2:E8000&""))/COUNTA(Responses!E2:E8000),0) -> 0 | F1: =IFERROR(SUMPRODUCT((Responses!F2:F8000<>"")/COUNTIF(Responses!F2:F8000,Responses!F2:F8000&""))/COUNTA(Responses!F2:F8000),0) -> 0 | G1: =IFERROR(SUMPRODUCT((Responses!G2:G8000<>"")/COUNTIF(Responses!G2:G8000,Responses!G2:G8000&""))/COUNTA(Responses!G2:G8000),0) -> 0 | H1: =IFERROR(SUMPRODUCT((Responses!H2:H8000<>"")/COUNTIF(Responses!H2:H8000,Responses!H2:H8000&""))/COUNTA(Responses!H2:H8000),0) -> 0 | ... ZZ1: =IFERROR(SUMPRODUCT((Responses!ZZ2:ZZ8000<>"")/COUNTIF(Responses!ZZ2:ZZ8000,Responses!ZZ2:ZZ8000&""))/COUNTA(Responses!ZZ2:ZZ8000),0) -> 0
A2: =COUNTA(Responses!A2:A8000) -> 0 | B2: =COUNTA(Responses!B2:B8000) -> 0 | C2: =COUNTA(Responses!C2:C8000) -> 0 | D2: =COUNTA(Responses!D2:D8000) -> 0 | E2: =COUNTA(Responses!E2:E8000) -> 0 | F2: =COUNTA(Responses!F2:F8000) -> 0 | G2: =COUNTA(Responses!G2:G8000) -> 0 | H2: =COUNTA(Responses!H2:H8000) -> 0 | ... ZZ2: =COUNTA(Responses!ZZ2:ZZ8000) -> 0
A3: Internal helpers — do not edit. Hidden by default.
A4: Open Q A L | B4: Open Q A H | C4: Open Q A a | D4: Open Q A b | E4: Open Q A na | F4: Open Q A nb | G4: Open Q A inter | H4: Open Q A sim | I4: Multip A L | J4: Multip A H | K4: Multip A a | L4: Multip A b | M4: Multip A na | N4: Multip A nb | O4: Multip A inter | P4: Multip A sim | Q4: Hybrid A L | R4: Hybrid A H | S4: Hybrid A a | T4: Hybrid A b | U4: Hybrid A na | V4: Hybrid A nb | W4: Hybrid A inter | X4: Hybrid A sim | Y4: Hybrid D L | Z4: Hybrid D H | AA4: Hybrid D a | AB4: Hybrid D b | AC4: Hybrid D na | AD4: Hybrid D nb | AE4: Hybrid D inter | AF4: Hybrid D sim
A5: ='Open Questions'!$A$2 -> 0 | B5: =IFERROR(INDEX(Responses!$1:$1,1,CHOOSE(LEN(TRIM($A$5)),CODE(TRIM($A$5))-64,(CODE(LEFT(TRIM($A$5),1))-64)*26+(CODE(RIGHT(TRIM($A$5),1))-64),(CODE(LEFT(TRIM($A$5),1))-64)*676+(CODE(MID(TRIM($A$5),2,1))-64)*26+(CODE(RIGHT(TRIM($A$5),1))-64))),"") -> 0 | C5: =LOWER(TRIM(LEFT('Open Questions'!$C$2,200))) -> 0 | D5: =LOWER(TRIM(LEFT($B$5,200))) -> 0 | E5: =MAX(LEN($C$5)-3,0) -> 0 | F5: =MAX(LEN($D$5)-3,0) -> 0 | G5: {=IF(OR($E$5<=0,$F$5<=0),0,SUMPRODUCT(--ISNUMBER(SEARCH(MID($C$5,_xlfn.SEQUENCE($E$5),4),$D$5))))} -> 0 | H5: =IF(OR($A$5="",$C$5="",$D$5="",$E$5<=0,$F$5<=0),"",$G$5/($E$5+$F$5-$G$5)) -> 0 | I5: ='Multiple Choice Questions'!$A$2 -> 0 | J5: =IFERROR(INDEX(Responses!$1:$1,1,CHOOSE(LEN(TRIM($I$5)),CODE(TRIM($I$5))-64,(CODE(LEFT(TRIM($I$5),1))-64)*26+(CODE(RIGHT(TRIM($I$5),1))-64),(CODE(LEFT(TRIM($I$5),1))-64)*676+(CODE(MID(TRIM($I$5),2,1))-64)*26+(CODE(RIGHT(TRIM($I$5),1))-64))),"") -> 0 | K5: =LOWER(TRIM(LEFT('Multiple Choice Questions'!$C$2,200))) -> 0 | L5: =LOWER(TRIM(LEFT($J$5,200))) -> 0 | M5: =MAX(LEN($K$5)-3,0) -> 0 | N5: =MAX(LEN($L$5)-3,0) -> 0 | O5: {=IF(OR($M$5<=0,$N$5<=0),0,SUMPRODUCT(--ISNUMBER(SEARCH(MID($K$5,_xlfn.SEQUENCE($M$5),4),$L$5))))} -> 0 | P5: =IF(OR($I$5="",$K$5="",$L$5="",$M$5<=0,$N$5<=0),"",$O$5/($M$5+$N$5-$O$5)) -> 0 | Q5: ='Hybrid Questions'!$A$2 -> 0 | R5: =IFERROR(INDEX(Responses!$1:$1,1,CHOOSE(LEN(TRIM($Q$5)),CODE(TRIM($Q$5))-64,(CODE(LEFT(TRIM($Q$5),1))-64)*26+(CODE(RIGHT(TRIM($Q$5),1))-64),(CODE(LEFT(TRIM($Q$5),1))-64)*676+(CODE(MID(TRIM($Q$5),2,1))-64)*26+(CODE(RIGHT(TRIM($Q$5),1))-64))),"") -> 0 | S5: =LOWER(TRIM(LEFT('Hybrid Questions'!$C$2,200))) -> 0 | T5: =LOWER(TRIM(LEFT($R$5,200))) -> 0 | U5: =MAX(LEN($S$5)-3,0) -> 0 | V5: =MAX(LEN($T$5)-3,0) -> 0 | W5: {=IF(OR($U$5<=0,$V$5<=0),0,SUMPRODUCT(--ISNUMBER(SEARCH(MID($S$5,_xlfn.SEQUENCE($U$5),4),$T$5))))} -> 0 | X5: =IF(OR($Q$5="",$S$5="",$T$5="",$U$5<=0,$V$5<=0),"",$W$5/($U$5+$V$5-$W$5)) -> 0 | Y5: ='Hybrid Questions'!$D$2 -> 0 | Z5: =IFERROR(INDEX(Responses!$1:$1,1,CHOOSE(LEN(TRIM($Y$5)),CODE(TRIM($Y$5))-64,(CODE(LEFT(TRIM($Y$5),1))-64)*26+(CODE(RIGHT(TRIM($Y$5),1))-64),(CODE(LEFT(TRIM($Y$5),1))-64)*676+(CODE(MID(TRIM($Y$5),2,1))-64)*26+(CODE(RIGHT(TRIM($Y$5),1))-64))),"") -> 0 | AA5: =LOWER(TRIM(LEFT('Hybrid Questions'!$C$2,200))) -> 0 | AB5: =LOWER(TRIM(LEFT($Z$5,200))) -> 0 | AC5: =MAX(LEN($AA$5)-3,0) -> 0 | AD5: =MAX(LEN($AB$5)-3,0) -> 0 | AE5: {=IF(OR($AC$5<=0,$AD$5<=0),0,SUMPRODUCT(--ISNUMBER(SEARCH(MID($AA$5,_xlfn.SEQUENCE($AC$5),4),$AB$5))))} -> 0 | AF5: =IF(OR($Y$5="",$AA$5="",$AB$5="",$AC$5<=0,$AD$5<=0),"",$AE$5/($AC$5+$AD$5-$AE$5)) -> 0
A6: ='Open Questions'!$A$3 -> 0 | B6: =IFERROR(INDEX(Responses!$1:$1,1,CHOOSE(LEN(TRIM($A$6)),CODE(TRIM($A$6))-64,(CODE(LEFT(TRIM($A$6),1))-64)*26+(CODE(RIGHT(TRIM($A$6),1))-64),(CODE(LEFT(TRIM($A$6),1))-64)*676+(CODE(MID(TRIM($A$6),2,1))-64)*26+(CODE(RIGHT(TRIM($A$6),1))-64))),"") -> 0 | C6: =LOWER(TRIM(LEFT('Open Questions'!$C$3,200))) -> 0 | D6: =LOWER(TRIM(LEFT($B$6,200))) -> 0 | E6: =MAX(LEN($C$6)-3,0) -> 0 | F6: =MAX(LEN($D$6)-3,0) -> 0 | G6: {=IF(OR($E$6<=0,$F$6<=0),0,SUMPRODUCT(--ISNUMBER(SEARCH(MID($C$6,_xlfn.SEQUENCE($E$6),4),$D$6))))} -> 0 | H6: =IF(OR($A$6="",$C$6="",$D$6="",$E$6<=0,$F$6<=0),"",$G$6/($E$6+$F$6-$G$6)) -> 0 | I6: ='Multiple Choice Questions'!$A$3 -> 0 | J6: =IFERROR(INDEX(Responses!$1:$1,1,CHOOSE(LEN(TRIM($I$6)),CODE(TRIM($I$6))-64,(CODE(LEFT(TRIM($I$6),1))-64)*26+(CODE(RIGHT(TRIM($I$6),1))-64),(CODE(LEFT(TRIM($I$6),1))-64)*676+(CODE(MID(TRIM($I$6),2,1))-64)*26+(CODE(RIGHT(TRIM($I$6),1))-64))),"") -> 0 | K6: =LOWER(TRIM(LEFT('Multiple Choice Questions'!$C$3,200))) -> 0 | L6: =LOWER(TRIM(LEFT($J$6,200))) -> 0 | M6: =MAX(LEN($K$6)-3,0) -> 0 | N6: =MAX(LEN($L$6)-3,0) -> 0 | O6: {=IF(OR($M$6<=0,$N$6<=0),0,SUMPRODUCT(--ISNUMBER(SEARCH(MID($K$6,_xlfn.SEQUENCE($M$6),4),$L$6))))} -> 0 | P6: =IF(OR($I$6="",$K$6="",$L$6="",$M$6<=0,$N$6<=0),"",$O$6/($M$6+$N$6-$O$6)) -> 0 | Q6: ='Hybrid Questions'!$A$3 -> 0 | R6: =IFERROR(INDEX(Responses!$1:$1,1,CHOOSE(LEN(TRIM($Q$6)),CODE(TRIM($Q$6))-64,(CODE(LEFT(TRIM($Q$6),1))-64)*26+(CODE(RIGHT(TRIM($Q$6),1))-64),(CODE(LEFT(TRIM($Q$6),1))-64)*676+(CODE(MID(TRIM($Q$6),2,1))-64)*26+(CODE(RIGHT(TRIM($Q$6),1))-64))),"") -> 0 | S6: =LOWER(TRIM(LEFT('Hybrid Questions'!$C$3,200))) -> 0 | T6: =LOWER(TRIM(LEFT($R$6,200))) -> 0 | U6: =MAX(LEN($S$6)-3,0) -> 0 | V6: =MAX(LEN($T$6)-3,0) -> 0 | W6: {=IF(OR($U$6<=0,$V$6<=0),0,SUMPRODUCT(--ISNUMBER(SEARCH(MID($S$6,_xlfn.SEQUENCE($U$6),4),$T$6))))} -> 0 | X6: =IF(OR($Q$6="",$S$6="",$T$6="",$U$6<=0,$V$6<=0),"",$W$6/($U$6+$V$6-$W$6)) -> 0 | Y6: ='Hybrid Questions'!$D$3 -> 0 | Z6: =IFERROR(INDEX(Responses!$1:$1,1,CHOOSE(LEN(TRIM($Y$6)),CODE(TRIM($Y$6))-64,(CODE(LEFT(TRIM($Y$6),1))-64)*26+(CODE(RIGHT(TRIM($Y$6),1))-64),(CODE(LEFT(TRIM($Y$6),1))-64)*676+(CODE(MID(TRIM($Y$6),2,1))-64)*26+(CODE(RIGHT(TRIM($Y$6),1))-64))),"") -> 0 | AA6: =LOWER(TRIM(LEFT('Hybrid Questions'!$C$3,200))) -> 0 | AB6: =LOWER(TRIM(LEFT($Z$6,200))) -> 0 | AC6: =MAX(LEN($AA$6)-3,0) -> 0 | AD6: =MAX(LEN($AB$6)-3,0) -> 0 | AE6: {=IF(OR($AC$6<=0,$AD$6<=0),0,SUMPRODUCT(--ISNUMBER(SEARCH(MID($AA$6,_xlfn.SEQUENCE($AC$6),4),$AB$6))))} -> 0 | AF6: =IF(OR($Y$6="",$AA$6="",$AB$6="",$AC$6<=0,$AD$6<=0),"",$AE$6/($AC$6+$AD$6-$AE$6)) -> 0
A7: ='Open Questions'!$A$4 -> 0 | B7: =IFERROR(INDEX(Responses!$1:$1,1,CHOOSE(LEN(TRIM($A$7)),CODE(TRIM($A$7))-64,(CODE(LEFT(TRIM($A$7),1))-64)*26+(CODE(RIGHT(TRIM($A$7),1))-64),(CODE(LEFT(TRIM($A$7),1))-64)*676+(CODE(MID(TRIM($A$7),2,1))-64)*26+(CODE(RIGHT(TRIM($A$7),1))-64))),"") -> 0 | C7: =LOWER(TRIM(LEFT('Open Questions'!$C$4,200))) -> 0 | D7: =LOWER(TRIM(LEFT($B$7,200))) -> 0 | E7: =MAX(LEN($C$7)-3,0) -> 0 | F7: =MAX(LEN($D$7)-3,0) -> 0 | G7: {=IF(OR($E$7<=0,$F$7<=0),0,SUMPRODUCT(--ISNUMBER(SEARCH(MID($C$7,_xlfn.SEQUENCE($E$7),4),$D$7))))} -> 0 | H7: =IF(OR($A$7="",$C$7="",$D$7="",$E$7<=0,$F$7<=0),"",$G$7/($E$7+$F$7-$G$7)) -> 0 | I7: ='Multiple Choice Questions'!$A$4 -> 0 | J7: =IFERROR(INDEX(Responses!$1:$1,1,CHOOSE(LEN(TRIM($I$7)),CODE(TRIM($I$7))-64,(CODE(LEFT(TRIM($I$7),1))-64)*26+(CODE(RIGHT(TRIM($I$7),1))-64),(CODE(LEFT(TRIM($I$7),1))-64)*676+(CODE(MID(TRIM($I$7),2,1))-64)*26+(CODE(RIGHT(TRIM($I$7),1))-64))),"") -> 0 | K7: =LOWER(TRIM(LEFT('Multiple Choice Questions'!$C$4,200))) -> 0 | L7: =LOWER(TRIM(LEFT($J$7,200))) -> 0 | M7: =MAX(LEN($K$7)-3,0) -> 0 | N7: =MAX(LEN($L$7)-3,0) -> 0 | O7: {=IF(OR($M$7<=0,$N$7<=0),0,SUMPRODUCT(--ISNUMBER(SEARCH(MID($K$7,_xlfn.SEQUENCE($M$7),4),$L$7))))} -> 0 | P7: =IF(OR($I$7="",$K$7="",$L$7="",$M$7<=0,$N$7<=0),"",$O$7/($M$7+$N$7-$O$7)) -> 0 | Q7: ='Hybrid Questions'!$A$4 -> 0 | R7: =IFERROR(INDEX(Responses!$1:$1,1,CHOOSE(LEN(TRIM($Q$7)),CODE(TRIM($Q$7))-64,(CODE(LEFT(TRIM($Q$7),1))-64)*26+(CODE(RIGHT(TRIM($Q$7),1))-64),(CODE(LEFT(TRIM($Q$7),1))-64)*676+(CODE(MID(TRIM($Q$7),2,1))-64)*26+(CODE(RIGHT(TRIM($Q$7),1))-64))),"") -> 0 | S7: =LOWER(TRIM(LEFT('Hybrid Questions'!$C$4,200))) -> 0 | T7: =LOWER(TRIM(LEFT($R$7,200))) -> 0 | U7: =MAX(LEN($S$7)-3,0) -> 0 | V7: =MAX(LEN($T$7)-3,0) -> 0 | W7: {=IF(OR($U$7<=0,$V$7<=0),0,SUMPRODUCT(--ISNUMBER(SEARCH(MID($S$7,_xlfn.SEQUENCE($U$7),4),$T$7))))} -> 0 | X7: =IF(OR($Q$7="",$S$7="",$T$7="",$U$7<=0,$V$7<=0),"",$W$7/($U$7+$V$7-$W$7)) -> 0 | Y7: ='Hybrid Questions'!$D$4 -> 0 | Z7: =IFERROR(INDEX(Responses!$1:$1,1,CHOOSE(LEN(TRIM($Y$7)),CODE(TRIM($Y$7))-64,(CODE(LEFT(TRIM($Y$7),1))-64)*26+(CODE(RIGHT(TRIM($Y$7),1))-64),(CODE(LEFT(TRIM($Y$7),1))-64)*676+(CODE(MID(TRIM($Y$7),2,1))-64)*26+(CODE(RIGHT(TRIM($Y$7),1))-64))),"") -> 0 | AA7: =LOWER(TRIM(LEFT('Hybrid Questions'!$C$4,200))) -> 0 | AB7: =LOWER(TRIM(LEFT($Z$7,200))) -> 0 | AC7: =MAX(LEN($AA$7)-3,0) -> 0 | AD7: =MAX(LEN($AB$7)-3,0) -> 0 | AE7: {=IF(OR($AC$7<=0,$AD$7<=0),0,SUMPRODUCT(--ISNUMBER(SEARCH(MID($AA$7,_xlfn.SEQUENCE($AC$7),4),$AB$7))))} -> 0 | AF7: =IF(OR($Y$7="",$AA$7="",$AB$7="",$AC$7<=0,$AD$7<=0),"",$AE$7/($AC$7+$AD$7-$AE$7)) -> 0
A8: ='Open Questions'!$A$5 -> 0 | B8: =IFERROR(INDEX(Responses!$1:$1,1,CHOOSE(LEN(TRIM($A$8)),CODE(TRIM($A$8))-64,(CODE(LEFT(TRIM($A$8),1))-64)*26+(CODE(RIGHT(TRIM($A$8),1))-64),(CODE(LEFT(TRIM($A$8),1))-64)*676+(CODE(MID(TRIM($A$8),2,1))-64)*26+(CODE(RIGHT(TRIM($A$8),1))-64))),"") -> 0 | C8: =LOWER(TRIM(LEFT('Open Questions'!$C$5,200))) -> 0 | D8: =LOWER(TRIM(LEFT($B$8,200))) -> 0 | E8: =MAX(LEN($C$8)-3,0) -> 0 | F8: =MAX(LEN($D$8)-3,0) -> 0 | G8: {=IF(OR($E$8<=0,$F$8<=0),0,SUMPRODUCT(--ISNUMBER(SEARCH(MID($C$8,_xlfn.SEQUENCE($E$8),4),$D$8))))} -> 0 | H8: =IF(OR($A$8="",$C$8="",$D$8="",$E$8<=0,$F$8<=0),"",$G$8/($E$8+$F$8-$G$8)) -> 0 | I8: ='Multiple Choice Questions'!$A$5 -> 0 | J8: =IFERROR(INDEX(Responses!$1:$1,1,CHOOSE(LEN(TRIM($I$8)),CODE(TRIM($I$8))-64,(CODE(LEFT(TRIM($I$8),1))-64)*26+(CODE(RIGHT(TRIM($I$8),1))-64),(CODE(LEFT(TRIM($I$8),1))-64)*676+(CODE(MID(TRIM($I$8),2,1))-64)*26+(CODE(RIGHT(TRIM($I$8),1))-64))),"") -> 0 | K8: =LOWER(TRIM(LEFT('Multiple Choice Questions'!$C$5,200))) -> 0 | L8: =LOWER(TRIM(LEFT($J$8,200))) -> 0 | M8: =MAX(LEN($K$8)-3,0) -> 0 | N8: =MAX(LEN($L$8)-3,0) -> 0 | O8: {=IF(OR($M$8<=0,$N$8<=0),0,SUMPRODUCT(--ISNUMBER(SEARCH(MID($K$8,_xlfn.SEQUENCE($M$8),4),$L$8))))} -> 0 | P8: =IF(OR($I$8="",$K$8="",$L$8="",$M$8<=0,$N$8<=0),"",$O$8/($M$8+$N$8-$O$8)) -> 0 | Q8: ='Hybrid Questions'!$A$5 -> 0 | R8: =IFERROR(INDEX(Responses!$1:$1,1,CHOOSE(LEN(TRIM($Q$8)),CODE(TRIM($Q$8))-64,(CODE(LEFT(TRIM($Q$8),1))-64)*26+(CODE(RIGHT(TRIM($Q$8),1))-64),(CODE(LEFT(TRIM($Q$8),1))-64)*676+(CODE(MID(TRIM($Q$8),2,1))-64)*26+(CODE(RIGHT(TRIM($Q$8),1))-64))),"") -> 0 | S8: =LOWER(TRIM(LEFT('Hybrid Questions'!$C$5,200))) -> 0 | T8: =LOWER(TRIM(LEFT($R$8,200))) -> 0 | U8: =MAX(LEN($S$8)-3,0) -> 0 | V8: =MAX(LEN($T$8)-3,0) -> 0 | W8: {=IF(OR($U$8<=0,$V$8<=0),0,SUMPRODUCT(--ISNUMBER(SEARCH(MID($S$8,_xlfn.SEQUENCE($U$8),4),$T$8))))} -> 0 | X8: =IF(OR($Q$8="",$S$8="",$T$8="",$U$8<=0,$V$8<=0),"",$W$8/($U$8+$V$8-$W$8)) -> 0 | Y8: ='Hybrid Questions'!$D$5 -> 0 | Z8: =IFERROR(INDEX(Responses!$1:$1,1,CHOOSE(LEN(TRIM($Y$8)),CODE(TRIM($Y$8))-64,(CODE(LEFT(TRIM($Y$8),1))-64)*26+(CODE(RIGHT(TRIM($Y$8),1))-64),(CODE(LEFT(TRIM($Y$8),1))-64)*676+(CODE(MID(TRIM($Y$8),2,1))-64)*26+(CODE(RIGHT(TRIM($Y$8),1))-64))),"") -> 0 | AA8: =LOWER(TRIM(LEFT('Hybrid Questions'!$C$5,200))) -> 0 | AB8: =LOWER(TRIM(LEFT($Z$8,200))) -> 0 | AC8: =MAX(LEN($AA$8)-3,0) -> 0 | AD8: =MAX(LEN($AB$8)-3,0) -> 0 | AE8: {=IF(OR($AC$8<=0,$AD$8<=0),0,SUMPRODUCT(--ISNUMBER(SEARCH(MID($AA$8,_xlfn.SEQUENCE($AC$8),4),$AB$8))))} -> 0 | AF8: =IF(OR($Y$8="",$AA$8="",$AB$8="",$AC$8<=0,$AD$8<=0),"",$AE$8/($AC$8+$AD$8-$AE$8)) -> 0
